<?xml version="1.0" encoding="utf-8"?>
<!-- This URDF was automatically created by SolidWorks to URDF Exporter! Originally created by Stephen Brawner (brawner@gmail.com) 
     Commit Version: 1.6.0-4-g7f85cfe  Build Version: 1.6.7995.38578
     For more information, please see http://wiki.ros.org/sw_urdf_exporter -->
<robot
  name="ANASA7">
  <link
    name="base_link">
    <inertial>
      <origin
        xyz="0.0409039885900863 -0.0933531694808405 0.0583530922483095"
        rpy="0 0 0" />
      <mass
        value="1.8049236132839" />
      <inertia
        ixx="0.00239355159848127"
        ixy="-5.28083887336829E-07"
        ixz="7.42025539306637E-05"
        iyy="0.00260834095667999"
        iyz="4.54611441209354E-06"
        izz="0.0039075436804005" />
    </inertial>
    <visual>
      <origin
        xyz="0 0 0"
        rpy="0 0 0" />
      <geometry>
        <mesh
          filename="package://ANASA7/meshes/base_link.STL" />
      </geometry>
      <material
        name="">
        <color
          rgba="0.627450980392157 0.63921568627451 0.568627450980392 1" />
      </material>
    </visual>
    <collision>
      <origin
        xyz="0 0 0"
        rpy="0 0 0" />
      <geometry>
        <mesh
          filename="package://ANASA7/meshes/base_link.STL" />
      </geometry>
    </collision>
  </link>
  <link
    name="Link_1">
    <inertial>
      <origin
        xyz="-0.00643460210920304 0.0172893971363355 -0.00137197240631336"
        rpy="0 0 0" />
      <mass
        value="0.0680382266926046" />
      <inertia
        ixx="5.81331813538308E-05"
        ixy="5.17764381970499E-06"
        ixz="-6.41736919561091E-07"
        iyy="5.467636163819E-05"
        iyz="6.24274411898596E-06"
        izz="4.5017720221946E-05" />
    </inertial>
    <visual>
      <origin
        xyz="0 0 0"
        rpy="0 0 0" />
      <geometry>
        <mesh
          filename="package://ANASA7/meshes/Link_1.STL" />
      </geometry>
      <material
        name="">
        <color
          rgba="0.792156862745098 0.819607843137255 0.933333333333333 1" />
      </material>
    </visual>
    <collision>
      <origin
        xyz="0 0 0"
        rpy="0 0 0" />
      <geometry>
        <mesh
          filename="package://ANASA7/meshes/Link_1.STL" />
      </geometry>
    </collision>
  </link>
  <joint
    name="q1"
    type="continuous">
    <origin
      xyz="0.0407792536350643 -0.0928795656917679 0.0931075741078677"
      rpy="1.5707963267949 0 0.886881487119416" />
    <parent
      link="base_link" />
    <child
      link="Link_1" />
    <axis
      xyz="0 1 0" />
  </joint>
  <link
    name="Link_2">
    <inertial>
      <origin
        xyz="-0.000129921421243601 0.0585889617137443 0.0059691150146594"
        rpy="0 0 0" />
      <mass
        value="0.0643957059523334" />
      <inertia
        ixx="0.000107041388075716"
        ixy="-9.12409869583641E-10"
        ixz="2.36256662975896E-10"
        iyy="9.11010442357688E-06"
        iyz="2.40343656089182E-07"
        izz="0.000111847761425141" />
    </inertial>
    <visual>
      <origin
        xyz="0 0 0"
        rpy="0 0 0" />
      <geometry>
        <mesh
          filename="package://ANASA7/meshes/Link_2.STL" />
      </geometry>
      <material
        name="">
        <color
          rgba="0 0.254901960784314 0.92156862745098 1" />
      </material>
    </visual>
    <collision>
      <origin
        xyz="0 0 0"
        rpy="0 0 0" />
      <geometry>
        <mesh
          filename="package://ANASA7/meshes/Link_2.STL" />
      </geometry>
    </collision>
  </link>
  <joint
    name="q2"
    type="continuous">
    <origin
      xyz="0 0.0404532568712267 -0.0137417296066946"
      rpy="-1.57079632679487 1.47629990543308 -1.57079632679487" />
    <parent
      link="Link_1" />
    <child
      link="Link_2" />
    <axis
      xyz="0 0 1" />
  </joint>
  <link
    name="Link_3">
    <inertial>
      <origin
        xyz="4.88362183498348E-07 0.0502090092246788 0.0126030370775675"
        rpy="0 0 0" />
      <mass
        value="0.0630340919810498" />
      <inertia
        ixx="8.7215788712602E-05"
        ixy="-1.5019811406081E-10"
        ixz="8.71200415750021E-12"
        iyy="1.03038432922002E-05"
        iyz="-7.58047091546378E-07"
        izz="9.44234738837451E-05" />
    </inertial>
    <visual>
      <origin
        xyz="0 0 0"
        rpy="0 0 0" />
      <geometry>
        <mesh
          filename="package://ANASA7/meshes/Link_3.STL" />
      </geometry>
      <material
        name="">
        <color
          rgba="0.792156862745098 0.819607843137255 0.933333333333333 1" />
      </material>
    </visual>
    <collision>
      <origin
        xyz="0 0 0"
        rpy="0 0 0" />
      <geometry>
        <mesh
          filename="package://ANASA7/meshes/Link_3.STL" />
      </geometry>
    </collision>
  </link>
  <joint
    name="q3"
    type="continuous">
    <origin
      xyz="0 0.12 0"
      rpy="3.14159265358979 0 -3.09177012713187" />
    <parent
      link="Link_2" />
    <child
      link="Link_3" />
    <axis
      xyz="0 0 1" />
  </joint>
  <link
    name="Link_4">
    <inertial>
      <origin
        xyz="0.0311399919225719 0.0108354271913698 0.0511717041418299"
        rpy="0 0 0" />
      <mass
        value="0.000559346607892399" />
      <inertia
        ixx="1.8191528312664E-07"
        ixy="-5.61159538522995E-09"
        ixz="-2.22056102012936E-08"
        iyy="2.05912423736136E-07"
        iyz="-2.18512722878733E-08"
        izz="5.35437863714727E-08" />
    </inertial>
    <visual>
      <origin
        xyz="0 0 0"
        rpy="0 0 0" />
      <geometry>
        <mesh
          filename="package://ANASA7/meshes/Link_4.STL" />
      </geometry>
      <material
        name="">
        <color
          rgba="0.843137254901961 0.815686274509804 0.752941176470588 1" />
      </material>
    </visual>
    <collision>
      <origin
        xyz="0 0 0"
        rpy="0 0 0" />
      <geometry>
        <mesh
          filename="package://ANASA7/meshes/Link_4.STL" />
      </geometry>
    </collision>
  </link>
  <joint
    name="q4"
    type="continuous">
    <origin
      xyz="0 0.0895 0"
      rpy="4 -1.5708 0" />
    <parent
      link="Link_3" />
    <child
      link="Link_4" />
    <axis
      xyz="1 0 0" />
  </joint>
</robot>